Workbook

Sheet Pivot Table 5
N1: Hasil
N2: Lolos Administrasi
N3: Lolos Administrasi
N4: Lolos Administrasi
N5: Lolos Administrasi
N6: Lolos Administrasi
N7: Tidak Lolos Administrasi | O7: belum diumumkan
N8: Lolos Administrasi
N9: Lolos Administrasi
N10: Lolos Administrasi
N11: Lolos Administrasi
N12: Tidak Lolos Administrasi
N13: Lolos Administrasi
N14: Tidak Lolos Administrasi
N15: Tidak Lolos Administrasi
N16: Lolos Administrasi
N17: Tidak Lolos Administrasi
N18: Lolos Administrasi
N19: Lolos Administrasi
... N90: Lolos Administrasi
A91: Kabupaten Buton Tengah, Sulawesi Tenggara | B91: Tenaga pendampingan pembelajaran mata pelajaran TIK | C91: muh. andy afdal., M.Pd., Gr | D91: 36160 | E91: Tadris Biologi | F91: 3.60 | G91: Biologi | H91: 3.91 | I91: https://drive.google.com/drive/folders/19r7Cl5nUN2M2MKhSE7bGX8tAGaPZ57JC | J91: 085242615796 | N91: Lolos Administrasi
B92: Kabupaten Buton Tengah - Tenaga pendampingan pembelajaran mata Pelajaran Pendidikan Pancasila | C92: Nuzulia Fitriana, S.Pd., M.Pd. | D92: 34986 | E92: Pendidikan Pancasila dan Kewarganegaraan | F92: 3.54 | G92: Pendidikan Pancasila dan Kewarganegaraan (PKn) | H92: - | I92: https://youtu.be/37xNnZIRYh8?si=ZntzwVImPe4feJBs | J92: 085702115262 | N92: Lolos Administrasi
B93: Kabupaten Jepara - Tenaga pendampingan pembelajaran mata Pelajaran Bahasa Inggris | C93: Dewi Inda Musni, S.Pd., Gr. | D93: 36000 | E93: Pendidikan IPA | F93: 3.70 | G93: Ilmu Pengetahuan Alam (IPA) | H93: 3.99 | I93: https://drive.google.com/drive/folders/1YLcx8j3x4rEq2EPc1oUEnY0ns2CZx521 | J93: 082323558624 | N93: Tidak Lolos Administrasi | O93: tidak linear
B94: Kabupaten Buton Tengah - Tenaga pendampingan pembelajaran mata pelajaran TIK | C94: Seno Setiyawan, S.Si, Gr | D94: 34873 | E94: Matematika | F94: 3.11 | G94: Matematika | H94: 3.90 | I94: https://drive.google.com/drive/folders/17MT469v6DaHmpoLFdWBe241N_dObmepV?usp=drive_link | J94: 085799588894 | N94: Tidak Lolos Administrasi | O94: IPK S1 dibawah 3.25
B95: Kabupaten Buton Tengah - Tenaga pendampingan pembelajaran mata pelajaran TIK | C95: Talitha Nabilah, S.Pd. Gr. | D95: 36964 | E95: Pendidikan Fisika | F95: 3.77 | G95: Pendidikan Guru Sekolah Dasar (PGSD) | H95: 3.96 | I95: https://drive.google.com/file/d/1esCIwzUph4H8JVvdlxBZpkGt2mgfGEOw/view?usp=sharing | J95: 082334453085 | N95: Tidak Lolos Administrasi | O95: tidak linear
B96: Kabupaten Jepara - Tenaga pendampingan pembelajaran mata Pelajaran Bahasa Inggris | C96: Fajar Ady Widyanto, S.Pd., Gr. | D96: 34480 | E96: Pendidikan Seni Rupa | F96: 3.10 | G96: Seni Budaya | H96: 3.91 | I96: https://drive.google.com/file/d/1cmV4eplHOudpvjZyn_HVJK6lNiw9g58G/view?usp=drivesdk | J96: 08135761188 | N96: Tidak Lolos Administrasi | O96: Umur, IPK, dan tidak linear
B97: Kabupaten Buton Tengah - Tenaga pendampingan pembelajaran mata pelajaran TIK | C97: Muhammad Mukammil, S.Pd., Gr | D97: 36856 | E97: Pendidikan Teknologi Informasi | F97: 3.73 | G97: Informatika | H97: 3.98 | I97: https://drive.google.com/file/d/1Y1HflIYtf8a__N_hRkDkNxk37uHu01vn/view?usp=drive_link | J97: 082236786534 | N97: Lolos Administrasi
B98: Kabupaten Buton Tengah - Tenaga pendampingan pembelajaran mata pelajaran TIK | C98: Vira Oktaviana, S.Pd.Gr | D98: 36441 | E98: Pendidikan Teknik Informatika dan Komputer | F98: 3.47 | G98: Informatika | H98: 3.96 | I98: https://drive.google.com/file/d/16iPyUf7iTQQhSLQ91kRa-Q5r3R0NU1Zz/view?usp=drive_link | J98: 085875666255 | N98: Lolos Administrasi
B99: Kabupaten Jepara - Tenaga pendampingan pembelajaran mata Pelajaran Bahasa Inggris | C99: Cahyo Tomi Prakoso, S.Pd., Gr. | D99: 35562 | E99: Pendidikan Bahasa Inggris | F99: 3.37 | G99: Bahasa Inggris | H99: 3.31 | I99: https://drive.google.com/file/d/1pC-5PPO96WmgmPD63ulKwXOSpWLxgzJw/view?usp=drivesdk | J99: 08993882246 | N99: Lolos Administrasi

Sheet Form Responses 1
A1: Timestamp | B1: Email Address | C1: Nama Lengkap (disertai gelar) | D1: PTK ID / SIMPKB ID | E1: Nomor WA | F1: Tanggal Lahir | G1: Program Studi S-1/D-IV | H1: Asal Universitas S-1/D-IV | I1: Bidang Studi PPG (sesuai yg tertulis di Serdik) | J1: Angkatan PPG | K1: Tahun Lulus PPG (sesuai dengan tahun penerbitan Sertifikat Pendidik) | L1: IPK saat S1 | M1: IPK saat PPG | N1: Domisili Anda saat ini? (Contoh : Kota Surakarta, Jawa Tengah) | O1: Berkedudukan sebagai calon PNS, PNS, PPPK, PPPK Paruh Waktu, prajurit Tentara Nasional Indonesia, atau anggota Kepolisian Negara Republik Indonesia; | P1: Jabatan dan Lokasi TPP yang dilamar | Q1: Pilihan Lokasi Sekolah Nasional Terintegrasi | R1: Sertifikat Pelatihan Peningkatan Komptenesi (5 tahun terakhir) | S1: Video Microteaching | T1: Kategori Pendaftar | U1: NIM PPG (dapat dilihat pada web: https://valid.fkip.uns.ac.id) | V1: NIM S1 | W1: Program Studi S1 | X1: LPTK PPG | Y1: NIM PPG | Z1: Upload Scan Sertifikat Pendidik (serdik) | AA1: Column 27 | AB1: Column 28 | AC1: Column 29 | AD1: Column 30 | AE1: Column 31 | AF1: Column 32
A2: 46231.922 | B2: rrizkhyadhi21@gmail.com | C2: Rizky Adi Nugroho S.Pd.,Gr. | D2: 7000247262 | E2: 085713086642 | F2: 36791 | G2: Pendidikan Jasmani | H2: UNIVERSITAS TUNAS PEMBANGUNAN SURAKARTA | I2: Pendidikan Jasmani, Olahraga, dan Kesehatan (PJOK) | J2: PPG Calon Guru Gelombang 2 Tahun 2024 | K2: 2025 | L2: 3.57 | M2: 3.88 | N2: Sukoharjo, Jawa Tengah | O2: Tidak | P2: Tenaga pendampingan pembelajaran mata Pelajaran Penjasorkes | Q2: Kabupaten Jepara, Jawa Tengah | R2: https://drive.google.com/drive/folders/1dsYqEqelctlZxB4Hys2aTvWw_xo7AZBD?usp=drive_link | S2: https://drive.google.com/file/d/1iCxSV9hd262CkcTCjL23f6n7t7EoV6ur/view?usp=sharing | T2: Alumni PPG Calon Guru / Prajabatan FKIP UNS | U2: X942408406 | V2: D0418008 | W2: PENDIDIKAN JASMANI | X2: UNIVERSITAS SEBELAS MARET SURAKARTA | Y2: X942408406
A3: 46229.615 | B3: puspitadianaarumawati@gmail.com | C3: Puspita Diana Arumawati, M.Pd., Gr. | D3: 7000086670 | E3: 082313256124 | F3: 36249 | G3: Pendidikan Biologi | H3: Universitas Negeri Semarang | I3: Biologi | J3: PPG Prajabatan Gelombang 2 Tahun 2022 | K3: 2023 | L3: 3.49 | M3: 3.94 | N3: Kabupaten Boyolali, Jawa Tengah | O3: Tidak | P3: Tenaga pendampingan pembelajaran mata Pelajaran Ilmu Pengetahuan Alam (IPA) untuk mengajar mata pelajaran Biologi, Kimia, Fisika | Q3: Kabupaten Jepara, Jawa Tengah | R3: https://drive.google.com/drive/folders/16x0nmGx6I5WGw8jgQGGJwL-c62fCaeiM?usp=drive_link | S3: https://drive.google.com/drive/folders/1LUwVcKfRJZTw2XbLLprTSDJ04eWDmd0c?usp=sharing | T3: Alumni PPG Calon Guru / Prajabatan FKIP UNS | U3: X9022084121 | V3: - | W3: - | X3: - | Y3: -
A4: 46229.615 | B4: hanafifuad33@gmail.com | C4: Fuad Hanafi, S.Pd., Gr. | D4: 7000266546 | E4: 087836197102 | F4: 37414 | G4: Pendidikan Bahasa dan Sastra Indonesia | H4: Universitas Muhammadiyah Surakarta | I4: Bahasa Indonesia | J4: PPG Prajabatan Gelombang 1 Tahun 2024 | K4: 2025 | L4: 3.79 | M4: 3.86 | N4: Sragen, Jawa Tengah | O4: Tidak | P4: Tenaga pendampingan pembelajaran mata Pelajaran Bahasa Indonesia | Q4: Kabupaten Jepara, Jawa Tengah | R4: https://drive.google.com/drive/folders/1sbX_gWwophHrTMrZOyC0f5Nbdw36cMSx | S4: https://drive.google.com/drive/folders/1nSG76BaQdtMG-CDvZEJRGPQJe22CUPnC | T4: Alumni PPG Calon Guru / Prajabatan FKIP UNS | U4: X942408195 | V4: - | W4: - | X4: Universitas Sebelas Maret | Y4: -
A5: 46230.947 | B5: nalapawitri81@gmail.com | C5: Nala Pawitri Andanawarih, S.Pd.,Gr | D5: 7000088952 | E5: 089515819690 | F5: 36154 | G5: Pendidikan Seni Tari | H5: Universitas Negeri Semarang | I5: Seni Budaya | J5: PPG Prajabatan Gelombang 1 Tahun 2023 | K5: 2024 | L5: 3.28 | M5: 3.86 | N5: Banyumas, Jawa Tengah | O5: Tidak | P5: Tenaga pendampingan pembelajaran mata Pelajaran Seni, Budaya, dan Prakarya | Q5: Kabupaten Jepara, Jawa Tengah | R5: - | S5: https://drive.google.com/drive/folders/1yCvx2arxXyITby30A4zMMaHb1zIP3NMt?hl=ID | T5: Alumni PPG Calon Guru / Prajabatan FKIP UNS | U5: X902308613 | V5: 2501417040 | W5: Pendidikan Seni Tari | X5: Universitas Sebelas Maret (UNS) | Y5: X902308613
A6: 46229.625 | B6: zahraarqam@gmail.com | C6: Sitti Zahra Riarana Arqam, S.Pd.Gr | D6: 700216115 | E6: 085399527002 | F6: 34744 | G6: Pendidikan Jasmani, Kesehatan dan Rekreasi | H6: Universitas Halu Oleo | I6: Pendidikan Jasmani, Olahraga, dan Kesehatan (PJOK) | J6: PPG Calon Guru Gelombang 2 Tahun 2024 | K6: 2025 | L6: 3.35 | M6: 4.00 | N6: Kota kendari, Sulawesi Tenggara | O6: Tidak | P6: Tenaga pendampingan pembelajaran mata Pelajaran Penjasorkes | Q6: Kabupaten Buton Tengah, Sulawesi Tenggara | R6: https://drive.google.com/file/d/1RTVKYZC70VNFZ0Li44B1okppAyidoSP2/view?usp=sharing | S6: https://drive.google.com/drive/folders/1v7ET-0MLyK3nfkDv6QSCOQu7jdaH58zl | T6: Alumni PPG Calon Guru / Prajabatan FKIP UHO | Y6: A3S224349
A7: 46229.728 | B7: ppg.syahnadinnuridha91@program.belajar.id | C7: SYAHNADIN NURIDHA, S. Pd., Gr | D7: 7000141094 | E7: 082322016171 | F7: 36178 | G7: S1 PENDIDIKAN IPA | H7: UNIVERSITAS NEGERI SEMARANG | I7: Ilmu Pengetahuan Alam (IPA) | J7: PPG Prajabatan Gelombang 1 Tahun 2023 | K7: 2024 | L7: 3.45 | M7: 3.94 | N7: SURAKARTA | O7: Tidak | P7: Tenaga pendampingan pembelajaran mata Pelajaran Ilmu Pengetahuan Alam (IPA) untuk mengajar mata pelajaran Biologi, Kimia, Fisika | Q7: Kabupaten Jepara, Jawa Tengah | R7: https://drive.google.com/drive/folders/1zI1VsvS3r7N2xgGHzHSOeXsPBlYpL9ku?usp=sharing | S7: https://drive.google.com/drive/folders/1zI1VsvS3r7N2xgGHzHSOeXsPBlYpL9ku?usp=sharing | T7: Alumni PPG Calon Guru / Prajabatan FKIP UNS | U7: X902308868 | V7: 4001417039 | W7: PENDIDIKAN IPA | X7: UNIVERSITAS SEBELAS MARET | Y7: X902308868
A8: 46231.355 | B8: syiadwi13@gmail.com | C8: Syifa Dwi Novita, S.Pd., Gr. | D8: 7000012366 | E8: 089608882627 | F8: 35747 | G8: S1 Pendidikan Biologi | H8: Universitas Muhammadiyah Purwokerto | I8: Ilmu Pengetahuan Alam (IPA) | J8: PPG Prajabatan Gelombang 1 Tahun 2023 | K8: 2024 | L8: 3.36 | M8: 3.98 | N8: Kedungrandu RT 1 RW 3, Kecamatan Patikraja, Kabupaten Banyumas | O8: Tidak | P8: Tenaga pendampingan pembelajaran mata Pelajaran Ilmu Pengetahuan Alam (IPA) untuk mengajar mata pelajaran Biologi, Kimia, Fisika | Q8: Kabupaten Jepara, Jawa Tengah | R8: https://drive.google.com/file/d/1X90srqhGWSBgzBIWf55Q0lMEEvUwXmVt/view?usp=sharing | S8: https://drive.google.com/drive/folders/1sDPOjTor3XOExzch1Qzi6KmtuS5XvMav?usp=drive_link | T8: Alumni PPG Calon Guru / Prajabatan FKIP UNS | U8: X902308871 | V8: 1501070008 | W8: S1 Pendidikan Biologi | X8: Universitas Sebelas Maret | Y8: -
A9: 46229.863 | B9: intaniaeka@gmail.com | C9: Intania Eka Yanti, S.Kom., Gr. | D9: 7000230682 | E9: 089662119850 | F9: 36233 | G9: S1 Sistem Informasi | H9: Universitas Telkom | I9: Informatika | J9: PPG Calon Guru Gelombang 2 Tahun 2024 | K9: 2025 | L9: 3.05 | M9: 3.94 | N9: Klaten, Jawa Tengah | O9: Tidak | P9: Tenaga pendampingan pembelajaran mata pelajaran TIK | Q9: Kabupaten Jepara, Jawa Tengah | R9: https://drive.google.com/drive/folders/1M6zYjueC4knG4C45THwrSOKv3fiE93TK?usp=sharing | S9: https://drive.google.com/drive/folders/1M6zYjueC4knG4C45THwrSOKv3fiE93TK?usp=sharing | T9: Alumni PPG Calon Guru / Prajabatan FKIP UNS | U9: X942408242 | V9: 1202174075 | W9: S1 Sistem Informasi | X9: Universitas Sebelas Maret | Y9: X942408242
A10: 46233.869 | B10: harnianisiti01.sa@gmail.com | C10: Siti Harniani, S. Pd | D10: 7000227911 | E10: 085342840408 | F10: 34581 | G10: Pendidikan Matematika | H10: Universitas Dayanu Ikhsanuddin | I10: Matematika | J10: PPG Prajabatan Gelombang 1 Tahun 2024 | K10: 2024 | L10: 3.57 | M10: 4.0 | N10: Kota Baubau, Sulawesi Tenggara | O10: Tidak | P10: Tenaga pendampingan pembelajaran mata Pelajaran Matematika (umum) | Q10: Kabupaten Buton Tengah, Sulawesi Tenggara | R10: https://drive.google.com/drive/folders/1W1SJkFGvffoQIz8_dEpLvZ7DVpQoENcq?usp=sharing | S10: https://drive.google.com/drive/folders/1w3AotyxcLiwjWuZcnqdtSFTGCadiF0xD?usp=sharing | T10: Alumni PPG Calon Guru / Prajabatan FKIP UHO | Y10: A3S224039
A11: 46229.968 | B11: adibirhamali@gmail.com | C11: Moch. Adib Irham Ali | D11: 7000202065 | E11: 081328698419 | F11: 35906 | G11: Pendidikan Sejarah | H11: Universitas Sebelas Maret | I11: Sejarah | J11: PPG Prajabatan Gelombang 2 Tahun 2023 | K11: 2024 | L11: 3.72 | M11: 4.00 | N11: Surakarta, Jawa Tengah | O11: Tidak | P11: Tenaga pendampingan pembelajaran mata Pelajaran Ilmu Pengetahuan Sosial (IPS) untuk mengajar mata pelajaran Sosiologi, Ekonomi, Geografi, dan Sejarah | Q11: Kabupaten Jepara, Jawa Tengah | R11: https://drive.google.com/drive/folders/14p8zvTWQB0cfS1KGcdo-A9IR61ZpUngs | S11: https://drive.google.com/drive/folders/14tm61sfbexmy9YMN6u3Mp_YaYsqT-5st | T11: Alumni PPG Calon Guru / Prajabatan FKIP UNS | U11: X9023083636 | V11: K4416037 | W11: Pendidikan Sejarah | X11: Universitas Sebelas Maret | Y11: X9023083636
A12: 46230.052 | B12: fitrinurhayani23@gmail.com | C12: Fitri Nurhayani, S.Pd | D12: 7000094807 | E12: 087719811922 | F12: 35825 | G12: Pendidikan Biologi | H12: Universitas Muhammadiyah Surakarta | I12: Ilmu Pengetahuan Alam (IPA) | J12: PPG Prajabatan Gelombang 1 Tahun 2023 | K12: 2024 | L12: 3.66 | M12: 3.97 | N12: Wonogiri, Jawa Tengah | O12: Tidak | P12: Tenaga pendampingan pembelajaran mata Pelajaran Ilmu Pengetahuan Alam (IPA) untuk mengajar mata pelajaran Biologi, Kimia, Fisika | Q12: Kabupaten Jepara, Jawa Tengah | R12: https://drive.google.com/drive/folders/1e8cKyNE3L_Zkdzx_WNKYqXprhRNVOZaq?usp=sharing | S12: https://drive.google.com/drive/folders/15ZPYQ3Clfe0EygnIfgBgzYEpRIik_sBB?usp=sharing | T12: Alumni PPG Calon Guru / Prajabatan FKIP UNS | U12: X902308362 | V12: 3.66 | W12: Pendidikan Biologi | X12: Universias Sebelas Maret (UNS) | Y12: X902308362
A13: 46230.071 | B13: asmildanurrahmawati@gmail.com | C13: Asmilda Nur Rahmawati S. Pd., Gr. | D13: 7000127861 | E13: 08999882330 | F13: 36756 | G13: Bimbingan dan konseling | H13: UNS | I13: Bimbingan dan Konseling | J13: PPG Prajabatan Gelombang 1 Tahun 2023 | K13: 2024 | L13: 3.65 | M13: 3.68 | N13: Kota Surakarta, Jawa Tengah | O13: Tidak | P13: Tenaga pendampingan pembelajaran mata Pelajaran Bimbingan dan Konseling | Q13: Kabupaten Jepara, Jawa Tengah | R13: https://drive.google.com/drive/folders/11lA10UXXoYhzvsfhUICgbtGtbGv8eSte | S13: https://drive.google.com/drive/folders/11lA10UXXoYhzvsfhUICgbtGtbGv8eSte | T13: Alumni PPG Calon Guru / Prajabatan FKIP UNS | U13: X902308141 | V13: K3118009 | W13: Bimbingan dan konseling | X13: Uns | Y13: -
A14: 46230.311 | B14: thaariqholland@student.uns.ac.id | C14: Muhammad Ath Thaariq Aziizi, S.Pd, Gr. | D14: 7000287279 | E14: 6281357514433 | F14: 36644 | G14: S-1 Pendidikan Sejarah | H14: Universitas Sebelas Maret | I14: Sejarah | J14: PPG Calon Guru Gelombang 2 Tahun 2024 | K14: 2025 | L14: 3.69 | M14: 3.84 | N14: Kabupaten Karanganyar, Jawa Tengah | O14: Tidak | P14: Tenaga pendampingan pembelajaran mata Pelajaran Ilmu Pengetahuan Sosial (IPS) untuk mengajar mata pelajaran Sosiologi, Ekonomi, Geografi, dan Sejarah | Q14: Kabupaten Jepara, Jawa Tengah | R14: https://uns.id/sertifpendidikanthaariq | S14: https://uns.id/veditukinthaariq | T14: Alumni PPG Calon Guru / Prajabatan FKIP UNS | U14: X942408310 | V14: K4419061 | W14: Pendidikan Sejarah | X14: Fakultas Ilmu Pendidikan dan Keguruan Universitas Sebelas Maret | Y14: -
A15: 46232.403 | B15: parifunm@gmail.com | C15: Parif, S.Pd., Gr. | D15: 7000193855 | E15: 085340567074 | F15: 36830 | G15: Pendidikan Akuntansi | H15: Universitas Negeri Makassar | I15: Akuntansi dan Keuangan | J15: PPG Calon Guru Gelombang 2 Tahun 2024 | K15: 2025 | L15: 3.63 | M15: 3.95 | N15: Kabupaten Maros | O15: Tidak | P15: Tenaga pendampingan pembelajaran mata Pelajaran Ilmu Pengetahuan Sosial (IPS) untuk mengajar mata pelajaran Sosiologi, Ekonomi, Geografi, dan Sejarah | Q15: Kabupaten Buton Tengah, Sulawesi Tenggara | R15: - | S15: https://drive.google.com/drive/folders/1GuUofoo8Ml4RxgfNRLC35L22Cqhy-kvo?usp=drive_link | T15: Alumni PPG Calon Guru / Prajabatan FKIP UNS | U15: X942408364 | V15: 1892041011 | W15: Pendidikan Akuntansi | X15: Universitas Negeri Makassar | Y15: X942408364
A16: 46231.633 | B16: nuningwijayanti248@gmail.com | C16: Nuning Wijayanti, S.Pd., Gr. | D16: 7000180386 | E16: 082323953038 | F16: 37225 | G16: S1 Pendidikan Bahasa dan Sastra Indonesia | H16: Universitas Tidar | I16: Bahasa Indonesia | J16: PPG Prajabatan Gelombang 2 Tahun 2023 | K16: 2024 | L16: 3.67 | M16: 3.73 | N16: Boyolali, Jawa Tengah | O16: Tidak | P16: Tenaga pendampingan pembelajaran mata Pelajaran Bahasa Indonesia | Q16: Kabupaten Jepara, Jawa Tengah | R16: https://drive.google.com/drive/folders/1PUlPUxJ9ULoWvGmLXEt0GU-YNtECwhXO | S16: https://drive.google.com/drive/folders/1cJkn_IoYOOXnOYMya1m1-G4ZZwiFqF5_ | T16: Alumni PPG Calon Guru / Prajabatan FKIP UNS | U16: X9023083681 | V16: 1910301058 | W16: Pendidikan Bahasa dan Sastra Indonesia | X16: Universitas Sebelas Maret | Y16: X9023083681
A17: 46231.74 | B17: ayum9003@gmail.com | C17: Mita Ayu Wulandari. S.Pd. | D17: 7000115177 | E17: 085238383337 | F17: 35061 | G17: Pendidikan Bahasa dan Sastra Indonesia | H17: Universitas Halu Oleo | I17: Bahasa Indonesia | J17: PPG Prajabatan Gelombang 1 Tahun 2023 | K17: 2024 | L17: 3.38 | M17: 4.00 | N17: Kota Kendari, Sulawesi Tenggara | O17: Tidak | P17: Tenaga pendampingan pembelajaran mata Pelajaran Bahasa Indonesia | Q17: Kabupaten Buton Tengah, Sulawesi Tenggara | R17: https://drive.google.com/drive/folders/12b_894tcCUKoJy5WHk7I7pof-VbaAG9v?usp=sharing | S17: https://drive.google.com/file/d/16I25Hub_4HCCCCFxaPj0dOUzgE7zysB3/view?usp=sharing | T17: Alumni PPG Calon Guru / Prajabatan FKIP UHO | Y17: A3S223077
A18: 46230.797 | B18: whhanatthahiraha8@gmail.com | C18: WH. HANAT THAHIRAH A., S.Pd, Gr. | D18: whhanatthahiraha8@gmail.com | E18: 082355139889 | F18: 37031 | G18: Pendidikan Biologi | H18: Universitas Halu Oleo | I18: Pendidikan Guru Sekolah Dasar (PGSD) | J18: PPG Calon Guru Gelombang 2 Tahun 2024 | K18: 2025 | L18: 3.42 | M18: 4.00 | N18: Kota Kendari, Sulawesi Tenggara | O18: Tidak | P18: Tenaga pendampingan pembelajaran mata Pelajaran Ilmu Pengetahuan Alam (IPA) untuk mengajar mata pelajaran Biologi, Kimia, Fisika | Q18: Kabupaten Buton Tengah, Sulawesi Tenggara | R18: https://drive.google.com/folderview?id=1-H0dgyCTkBx1Sx2sbwB_7BZN52kyclaR | S18: https://drive.google.com/folderview?id=1-GJrqYOfO4bnWQzG1X4FXH_EjpFWvBSi | T18: Alumni PPG Calon Guru / Prajabatan FKIP UHO | Y18: A3S224310
A19: 46230.886 | B19: azizahfajriatul@gmail.com | C19: Fajriatul 'Azizah | D19: 7000058324 | E19: 085743571470 | F19: 34712 | G19: Akuntansi | H19: Universitas Muhammadiyah Magelang | I19: Akuntansi dan Keuangan | J19: PPG Calon Guru Gelombang 2 Tahun 2024 | K19: 2025 | L19: 3.82 | M19: 3.98 | N19: Kabupaten Magelang | O19: Tidak | P19: Tenaga pendampingan pembelajaran mata Pelajaran Ilmu Pengetahuan Sosial (IPS) untuk mengajar mata pelajaran Sosiologi, Ekonomi, Geografi, dan Sejarah | Q19: Kabupaten Jepara, Jawa Tengah | R19: https://drive.google.com/drive/folders/1m91u-ixafYRtV4PP1DwSgpzZITA4pMTK?usp=sharing | S19: https://drive.google.com/file/d/1ZM2qaVqkQD-_tnv9zBhxAM7nrL9WyS0c/view?usp=drive_link | T19: Alumni PPG Calon Guru / Prajabatan FKIP UNS | U19: X942408172 | V19: 1601020011 | W19: Akuntansi | X19: Universitas Sebelas Maret | Y19: X942408172
A20: 46230.9 | B20: afrilianto@student.uns.ac.id | C20: Afri Lianto, S.Pd., Gr. | D20: 7000158269 | E20: 085740702984 | F20: 36262 | G20: S-1 | H20: Universitas Negeri Yogyakarta | I20: Pendidikan Jasmani, Olahraga, dan Kesehatan (PJOK) | J20: PPG Prajabatan Gelombang 1 Tahun 2023 | K20: 2024 | L20: 3.55 | M20: 3.98 | N20: Desa Krenceng, Rt 02 Rw 01 Kec.Kejobong, Kab.Purbingga, Jawa Tengah | O20: Tidak | P20: Tenaga pendampingan pembelajaran mata Pelajaran Penjasorkes | Q20: Kabupaten Jepara, Jawa Tengah | R20: https://drive.google.com/drive/folders/1qirwr70MFDx3AkmSPCtOXtF91TmXq43v | S20: https://drive.google.com/drive/folders/1PzS9P01UHo8ahunVVv6jD4ARfGViRjOG | T20: Alumni PPG Calon Guru / Prajabatan FKIP UNS | U20: X902308022 | V20: - | W20: - | X20: - | Y20: -
A21: 46230.949 | B21: ppg.lailamuniroh92@program.belajar.id | C21: Laila Magfirul Muniroh, S.Pd,. Gr | D21: 7000133033 | E21: 082138175793 | F21: 36520 | G21: Pendidikan Sejarah | H21: Universitas Sebelas Maret | I21: Sejarah | J21: PPG Prajabatan Gelombang 2 Tahun 2023 | K21: 2024 | L21: 3.71 | M21: 3.98 | N21: Kota Surakarta, Jawa Tengah | O21: Tidak | P21: Tenaga pendampingan pembelajaran mata Pelajaran Ilmu Pengetahuan Sosial (IPS) untuk mengajar mata pelajaran Sosiologi, Ekonomi, Geografi, dan Sejarah | Q21: Kabupaten Jepara, Jawa Tengah | R21: https://drive.google.com/drive/folders/1qtGqu3dQCug1Ta3kijfkP0VPhlHpTTpT?usp=drive_link | S21: https://drive.google.com/drive/folders/19wdv2SGiikjLmsRGeg6Us3PtGVYARdEH?usp=sharing | T21: Alumni PPG Calon Guru / Prajabatan FKIP UNS | U21: X9023083600 | V21: K4418039 | W21: Pendidikan Sejarah | X21: Universitas Sebelas Maret | Y21: X9023083600
A22: 46231.161 | B22: ppg.imronkamaludin02@program.belajar.id | C22: Imron Arya Kamaludin, S.Pd., Gr. | D22: 7000124340 | E22: 085712992243 | F22: 36584 | G22: S1 Pendidikan Biologi | H22: Universitas Tidar | I22: Ilmu Pengetahuan Alam (IPA) | J22: PPG Prajabatan Gelombang 1 Tahun 2023 | K22: 2024 | L22: 3.63 | M22: 3.98 | N22: Kabupaten Kebumen, Jawa Tengah | O22: Tidak | P22: Tenaga pendampingan pembelajaran mata Pelajaran Ilmu Pengetahuan Alam (IPA) untuk mengajar mata pelajaran Biologi, Kimia, Fisika | Q22: Kabupaten Jepara, Jawa Tengah | R22: https://drive.google.com/drive/folders/1L5fpaS1ICiKr9JtvjgoxgIawdl_9z-EH?usp=sharing | S22: https://drive.google.com/drive/folders/18L-lFRallenmFr2eSdMYor8T3gFby5iv?usp=sharing | T22: Alumni PPG Calon Guru / Prajabatan FKIP UNS | U22: X902308432 | V22: - | W22: - | X22: - | Y22: -
A23: 46231.367 | B23: rizqi.nurfitriani@student.uns.ac.id | C23: Rizqi Nur Fitriani | D23: 7000128901 | E23: 082329681100 | F23: 36613 | G23: Pendidikan Fisika | H23: Universitas Sebelas Maret | I23: Ilmu Pengetahuan Alam (IPA) | J23: PPG Prajabatan Gelombang 1 Tahun 2023 | K23: 2024 | L23: 3.62 | M23: 3.96 | N23: Kabupaten Pati | O23: Tidak | P23: Tenaga pendampingan pembelajaran mata Pelajaran Ilmu Pengetahuan Alam (IPA) untuk mengajar mata pelajaran Biologi, Kimia, Fisika | Q23: Kabupaten Jepara, Jawa Tengah | R23: https://drive.google.com/drive/folders/13-I7mBQQA8ynEqdL74VxwPk3mvJOc4i4 | S23: https://drive.google.com/drive/folders/1lbHZOdolmlsxx6yX2iLAARnS1OT7OdSP | T23: Alumni PPG Calon Guru / Prajabatan FKIP UNS | U23: X902308789 | V23: K2318059 | W23: Pendidikan fisika | X23: UNS | Y23: -
A24: 46231.439 | B24: nilasafitri3@gmail.com | C24: Nila Safitri, S.Pd., Gr. | D24: 7000130658 | E24: 082324551642 | F24: 36237 | G24: Pendidikan Bahasa Jawa | H24: UNIVERSITAS SEBELAS MARET | I24: Bahasa Jawa | J24: PPG Prajabatan Gelombang 1 Tahun 2023 | K24: 2024 | L24: 3.74 | M24: 4.00 | N24: Karanganyar, Jawa Tengah | O24: Tidak | P24: Tenaga pendampingan pembelajaran mata Pelajaran Seni, Budaya, dan Prakarya | Q24: Kabupaten Jepara, Jawa Tengah | R24: https://drive.google.com/drive/folders/1adI29tKHJKq3bur8xGZSWfHHrhJWKmVY | S24: https://drive.google.com/drive/folders/1IBUHZ570KJFy5CmkAqk3hdSbP9e0B9cp | T24: Alumni PPG Calon Guru / Prajabatan FKIP UNS | U24: X902308627 | V24: K4217052 | W24: Pendidikan Bahasa Jawa | X24: UNIVERSITAS SEBELAS MARET | Y24: -
A25: 46231.536 | B25: firdaauliashalihah@gmail.com | C25: Firda Aulia Shalihah, S.Pd., Gr. | D25: 7000237077 | E25: 0838-9183-0300 | F25: 36124 | G25: Pendidikan Bahasa dan Sastra Indonesia | H25: Universitas Jember | I25: Bahasa Indonesia | J25: PPG Calon Guru Gelombang 2 Tahun 2024 | K25: 2025 | L25: 3.82 | M25: 3.96 | N25: Kabupaten Bondowoso, Jawa Timur | O25: Tidak | P25: Tenaga pendampingan pembelajaran mata Pelajaran Bahasa Indonesia | Q25: Kabupaten Jepara, Jawa Tengah | R25: https://drive.google.com/drive/folders/1tEAq9LnaQpzTD0-eTxuLY8gkiO9MuXKQ?usp=sharing | S25: https://drive.google.com/file/d/14HJ3UJHAzqXiOJWas24_Koh5HDncUtR-/view?usp=sharing | T25: Alumni S1 FKIP UNS yang telah lulus PPG Calon Guru/Prajabatan bukan di FKIP UNS | V25: 160210402005 | W25: Pendidikan Bahasa dan Sastra Indonesia | X25: Universitas Jember | Y25: 240211920199
A26: 46231.538 | B26: nur116775@gmail.com | C26: Nur Awaliyah, S.Pd | D26: 7000046967 | E26: 08813904359 | F26: 35739 | G26: S1 Tadris Bahasa Inggris | H26: Universitas Islam Negeri Salatiga | I26: Bahasa Inggris | J26: PPG Prajabatan Gelombang 2 Tahun 2022 | K26: 2023 | L26: 3.74 | M26: - | N26: Kota Salatiga, Jawa Tengah | O26: Tidak | P26: Tenaga pendampingan pembelajaran mata Pelajaran Bahasa Inggris | Q26: Kabupaten Jepara, Jawa Tengah | R26: https://drive.google.com/drive/folders/1k_AcGyq3Q6qsc9WEwa0jYfv1W0X4zc2g?usp=sharing | S26: https://drive.google.com/drive/folders/1hp2AsPIKeEgMhUWbzwgDRHlp34wSTNCN?usp=sharing | T26: Alumni S1 FKIP UNS yang telah lulus PPG Calon Guru/Prajabatan bukan di FKIP UNS | V26: 23030150077 | W26: S1 Tadris Bahasa Inggris | X26: Universitas Negeri Semarang | Y26: 2201022236
A27: 46231.549 | B27: imamsetiawan101010@gmail.com | C27: Imam Setiawan, S.Pd., Gr., M.Pd. | D27: 7000157175 | E27: 085159559810 | F27: 36078 | G27: Pendidikan Biologi | H27: UMS | I27: Ilmu Pengetahuan Alam (IPA) | J27: PPG Prajabatan Gelombang 1 Tahun 2023 | K27: 2024 | L27: 3.38 | M27: 3.94 | N27: Boyolali, Jawa Tengah | O27: Tidak | P27: Tenaga pendampingan pembelajaran mata Pelajaran Ilmu Pengetahuan Alam (IPA) untuk mengajar mata pelajaran Biologi, Kimia, Fisika | Q27: Kabupaten Jepara, Jawa Tengah | R27: https://drive.google.com/drive/folders/1gZ-dtO59v_zpZMFk_rlSncfOBy3CNMlI | S27: https://drive.google.com/drive/folders/1ziBRYwAgtkkyPnTwpaQQlUVLoINNFHrH | T27: Alumni PPG Calon Guru / Prajabatan FKIP UNS | U27: X902308431 | V27: A420170009 | W27: Pendidikan Biologi | X27: UNS | Y27: X902308431
A28: 46231.566 | B28: mustofanuril71@gmail.com | C28: NURIL MUSTOFA, S.E., Gr. | D28: 7000330445 | E28: 08996579665 | F28: 37538 | G28: Akuntansi | H28: Universitas Negeri Semarang | I28: Akuntansi dan Keuangan | J28: PPG Calon Guru Gelombang 2 Tahun 2024 | K28: 2025 | L28: 3.77 | M28: 3.95 | N28: Kabupaten Jepara, Jawa Tengah | O28: Tidak | P28: Tenaga pendampingan pembelajaran mata Pelajaran Ilmu Pengetahuan Sosial (IPS) untuk mengajar mata pelajaran Sosiologi, Ekonomi, Geografi, dan Sejarah | Q28: Kabupaten Jepara, Jawa Tengah | R28: https://drive.google.com/drive/folders/1bnp3dRme-Dr3vc9InIaUR0cB0yXpXWIB?usp=sharing | S28: https://drive.google.com/drive/folders/18O0MONVMBSmYlQuiTTTxKi2Ty4RuE13V?usp=sharing | T28: Alumni PPG Calon Guru / Prajabatan FKIP UNS | U28: X942408355 | V28: - | W28: - | X28: - | Y28: -
A29: 46231.609 | B29: allikafh12@gmail.com | C29: Allika Fadiyah Hasna, S.Pd., Gr | D29: 7000166435 | E29: 0895422101144 | F29: 36893 | G29: Pendidikan Bahasa dan Sastra Indonesia | H29: STKIP NU INDRAMAYU | I29: Bahasa Indonesia | J29: PPG Prajabatan Gelombang 2 Tahun 2023 | K29: 2024 | L29: 3.71 | M29: 4 | N29: Jepara, Jawa Tengah | O29: Tidak | P29: Tenaga pendampingan pembelajaran mata Pelajaran Bahasa Indonesia | Q29: Kabupaten Jepara, Jawa Tengah | R29: https://drive.google.com/drive/folders/1udkPKpK1nytH6b-EDpdcT6Od2JddCBv0?usp=drive_link | S29: https://drive.google.com/file/d/1Eaqx9EWaqZ9QKFvtgEjSf1OH0v-fotPS/view?usp=drive_link | T29: Alumni PPG Calon Guru / Prajabatan FKIP UNS | U29: X9023083406 | V29: 1888201031 | W29: Pendidikan Bahasa dan Sastra Indonesia | X29: Universitas Sebelas Maret | Y29: X9023083406
A30: 46231.74 | B30: mroyyan2001@gmail.com | C30: Muhammad Royyan, S.Pd.,Gr. | D30: 7000291731 | E30: 085602502916 | F30: 37099 | G30: Pendidikan Informatika | H30: Universitas Ivet Semarang | I30: Informatika | J30: PPG Calon Guru Gelombang 2 Tahun 2024 | K30: 2025 | L30: 3.8 | M30: 3.98 | N30: Kabupaten Boyolali, Jawa Tengah | O30: Tidak | P30: Tenaga pendampingan pembelajaran mata pelajaran TIK | Q30: Kabupaten Jepara, Jawa Tengah | R30: https://drive.google.com/drive/folders/106d7lnYeq5BLtiUnJLXPSLeoEJCTNUMm | S30: https://drive.google.com/drive/folders/1PQQxwZNzVypS3yGp4a0HX6Wmibz9ALEQ | T30: Alumni PPG Calon Guru / Prajabatan FKIP UNS | U30: X942408324 | V30: - | W30: - | X30: - | Y30: -
A31: 46231.758 | B31: rosliana.1113@guru.smp.belajar.id | C31: Rosliana,S.Pd | D31: 202200123884 | E31: 085395341807 | F31: 34981 | G31: Pendidikan Matematika | H31: Universitas Islam Negeri Alauddin Makassar | I31: Matematika | J31: PPG Calon Guru Gelombang 2 Tahun 2024 | K31: 2025 | L31: 3.71 | M31: 4.00 | N31: Kota Kendari, Sulawesi Tenggara | O31: Tidak | P31: Tenaga pendampingan pembelajaran mata Pelajaran Matematika (umum) | Q31: Kabupaten Buton Tengah, Sulawesi Tenggara | R31: - | S31: https://drive.google.com/drive/folders/1yVRF9S8gmJh2aANEg8KX6ndxm6WfzhOc?usp=sharing | T31: Alumni PPG Calon Guru / Prajabatan FKIP UHO | Y31: A3S224280
A32: 46231.845 | B32: susiir1009@gmail.com | C32: Susi Susanti, S.Pd.,Gr | D32: 7000239728 | E32: 085256386808 | F32: 37214 | G32: Tadris matematika | H32: Institut Agama Islam Negeri (IAIN) Kendari | I32: Matematika | J32: PPG Calon Guru Gelombang 2 Tahun 2024 | K32: 2025 | L32: 3.59 | M32: 4.00 | N32: Konawe Utara, Sulawesi Tenggara | O32: Tidak | P32: Tenaga pendampingan pembelajaran mata Pelajaran Matematika (umum) | Q32: Kabupaten Buton Tengah, Sulawesi Tenggara | R32: - | S32: https://drive.google.com/file/d/1L2HeacFitfJzYYLnhEHSiZpRNZi6DIfH/view?usp=drivesdk | T32: Alumni PPG Calon Guru / Prajabatan FKIP UHO | Y32: A3S224286
A33: 46231.848 | B33: sartikasarti161@gmail.com | C33: Sartika,S.Pd., Gr. | D33: 7000143754 | E33: 085395374324 | F33: 36870 | G33: Pendidikan Bahasa dan Sastra Indonesia | H33: Universitas Halu Oleo | I33: Bahasa Indonesia | J33: PPG Prajabatan Gelombang 1 Tahun 2023 | K33: 2024 | L33: 3.58 | M33: 4.00 | N33: Kabupaten Muna, Sulawesi Tenggara | O33: Tidak | P33: Tenaga pendampingan pembelajaran mata Pelajaran Bahasa Indonesia | Q33: Kabupaten Buton Tengah, Sulawesi Tenggara | R33: - | S33: https://drive.google.com/file/d/11wzIy8pLPUhf9NFE6RP2ma53wXYu3e4C/view?usp=drivesdk | T33: Alumni PPG Calon Guru / Prajabatan FKIP UHO | Y33: A3S223076
A34: 46231.857 | B34: fitawardani1301@gmail.com | C34: Fita Wardani, S.Pd., Gr. | D34: 7000145964 | E34: 081938900154 | F34: 36538 | G34: Pendidikan Bahasa dan Sastra Indonesia | H34: Universitas Halu Oleo | I34: Bahasa Indonesia | J34: PPG Prajabatan Gelombang 1 Tahun 2023 | K34: 2024 | L34: 3.46 | M34: 4.00 | N34: Kabupaten Muna, Sulawesi Tenggara | O34: Tidak | P34: Tenaga pendampingan pembelajaran mata Pelajaran Bahasa Indonesia | Q34: Kabupaten Buton Tengah, Sulawesi Tenggara | R34: - | S34: https://drive.google.com/drive/folders/1SNu-qFtK02OmLkQZ1AWo5DDVTH46tRqo | T34: Alumni PPG Calon Guru / Prajabatan FKIP UHO | Y34: A3S223069
A35: 46231.869 | B35: ppg.adityahasan00828@program.belajar.id | C35: Aditya Maulana Hasan, S.Pd., Gr. | D35: 7000147570 | E35: 088809402034 | F35: 36759 | G35: S-1 Pendidikan Pancasila dan Kewarganegaraan (PPKn) | H35: Universitas Slamet Riyadi Surakarta | I35: Pendidikan Pancasila dan Kewarganegaraan (PKn) | J35: PPG Prajabatan Gelombang 2 Tahun 2023 | K35: 2024 | L35: 3.93 | M35: 3.91 | N35: Surakarta, Jawa Tengah | O35: Tidak | P35: Tenaga pendampingan pembelajaran mata Pelajaran Pendidikan Pancasila | Q35: Kabupaten Jepara, Jawa Tengah | R35: https://drive.google.com/drive/folders/1KQEjYEuRliiWwNZ-UeRxx7vH3kFna984?usp=drive_link | S35: https://drive.google.com/file/d/1zV2figavABF53g88ty1zBwjNJ4TwwTWj/view?usp=drivesdk | T35: Alumni PPG Calon Guru / Prajabatan FKIP UNS | U35: X9023083372 | V35: 19510009 | W35: Universitas Slamet Riyadi Surakarta | X35: Universitas Sebelas Maret Surakarta (UNS) | Y35: -
A36: 46231.875 | B36: tiwikhapsari55@gmail.com | C36: Nur Pratiwi Yuga Hapsari, S.Pd,.Gr | D36: 202500039736 | E36: 081393894231 | F36: 35987 | G36: Pendidikan Ekonomi | H36: Universitas Sebelas Maret | I36: Ekonomi | J36: PPG Prajabatan Gelombang 2 Tahun 2022 | K36: 2023 | L36: 3.46 | M36: 3.85 | N36: Surakarta, Jawa Tengah | O36: Tidak | P36: Tenaga pendampingan pembelajaran mata Pelajaran Ilmu Pengetahuan Sosial (IPS) untuk mengajar mata pelajaran Sosiologi, Ekonomi, Geografi, dan Sejarah | Q36: Kabupaten Jepara, Jawa Tengah | R36: https://drive.google.com/drive/folders/1Eg6r0rlH0F6MAdubmYPJPFh87S0nvJrm | S36: https://drive.google.com/drive/folders/1ZemobWCxQpWbWK-4F6mIDlYPJB6PQgHU | T36: Alumni S1 FKIP UNS yang telah lulus PPG Calon Guru/Prajabatan bukan di FKIP UNS | V36: K7616051 | W36: Pendidikan Ekonomi | X36: Universitas Sebelas Maret | Y36: X9022084096
A37: 46231.881 | B37: peserta.06995@ppg.belajar.id | C37: Listia Nuraini, S.Pd.,Gr | D37: 7000116289 | E37: 085840043140 | F37: 36432 | G37: Pendidikan Teknologi Informasi | H37: Universitas Teknologi Yogyakarta | I37: Informatika | J37: PPG Calon Guru Gelombang 2 Tahun 2024 | K37: 2025 | L37: 3.92 | M37: 3.97 | N37: Lampung selatan, Lampung | O37: Tidak | P37: Tenaga pendampingan pembelajaran mata pelajaran TIK | Q37: Kabupaten Jepara, Jawa Tengah | R37: - | S37: https://drive.google.com/drive/folders/19MRaOM80DF038NWPqHaqqcWNbEgyOpsX | T37: Alumni PPG Calon Guru / Prajabatan FKIP UNS | U37: X942408276 | V37: 5171311001 | W37: Pendidikan Teknologi Informasi | X37: Universitas Sebelas Maret | Y37: X942408276
A38: 46231.887 | B38: chabibahnur7@gmail.com | C38: Nurchabibah, S.Pd. | D38: 7000019417 | E38: 085710424577 | F38: 34964 | G38: Pendidikan Geografi | H38: Universitas Negeri Semarang | I38: Geografi | J38: PPG Prajabatan Gelombang 1 Tahun 2022 | K38: 2023 | L38: 3.45 | M38: 3.94 | N38: Purworejo, Jawa Tengah | O38: Tidak | P38: Tenaga pendampingan pembelajaran mata Pelajaran Ilmu Pengetahuan Sosial (IPS) untuk mengajar mata pelajaran Sosiologi, Ekonomi, Geografi, dan Sejarah | Q38: Kabupaten Jepara, Jawa Tengah | R38: https://drive.google.com/drive/folders/18oRqAvm67ggqMfNCM47RhToEBBLw5A_4?usp=sharing | S38: https://drive.google.com/drive/folders/1YHV5XDphM0hO8XmD0XXIw26hn__uS09N | T38: Alumni PPG Calon Guru / Prajabatan FKIP UNS | U38: X9022082584 | V38: - | W38: - | X38: - | Y38: -
A39: 46231.886 | B39: ppg.sucityas99428@program.belajar.id | C39: Suci Suryaning Tyas S.Pd,Gr | D39: 7000181406 | E39: 085725604967 | F39: 36253 | G39: S1 Pendidikan Seni Tari | H39: Universitas Negeri Semarang | I39: Seni Budaya | J39: PPG Prajabatan Gelombang 2 Tahun 2023 | K39: 2024 | L39: 3.49 | M39: 3.87 | N39: Kecamatan Susukan, Kabupaten Semarang, Jawa Tengah | O39: Tidak | P39: Tenaga pendampingan pembelajaran mata Pelajaran Seni, Budaya, dan Prakarya | Q39: Kabupaten Jepara, Jawa Tengah | R39: https://drive.google.com/drive/folders/1zgl0YiZyomWwF6BEe19h0ZLsRC-Uf7It | S39: https://drive.google.com/file/d/1iq8cDdVfuoJxTaGIJK-5C0uFxCjY3984/view?usp=drivesdk | T39: Alumni PPG Calon Guru / Prajabatan FKIP UNS | U39: X9023083785 | V39: - | W39: - | X39: UNS | Y39: -
A40: 46231.891 | B40: senosetiyawan23@gmail.com | C40: Seno setiyawan | D40: 7000110408 | E40: 085799588894 | F40: 34873 | G40: Matematika | H40: Universitas Sebelas Maret | I40: Matematika | J40: PPG Prajabatan Gelombang 2 Tahun 2023 | K40: 2024 | L40: 3.11 | M40: 3.90 | N40: Surakarta, Jawa Tengah | O40: Tidak | P40: Tenaga pendampingan pembelajaran mata Pelajaran Matematika (umum) | Q40: Kabupaten Jepara, Jawa Tengah | R40: https://drive.google.com/drive/folders/17MT469v6DaHmpoLFdWBe241N_dObmepV?usp=drive_link | S40: https://drive.google.com/drive/folders/17MT469v6DaHmpoLFdWBe241N_dObmepV?usp=drive_link | T40: Alumni PPG Calon Guru / Prajabatan FKIP UNS | U40: X9023083767 | V40: M0113045 | W40: Matematika | X40: Universitas Sebelas Maret | Y40: -
...

Sheet Admin Tahap 2
A1: =IFERROR(__xludf.DUMMYFUNCTION("QUERY('Form Responses 1'!A:Z, ""SELECT *"", 1)"),"Timestamp") -> Timestamp | B1: =IFERROR(__xludf.DUMMYFUNCTION("""COMPUTED_VALUE"""),"Email Address") -> Email Address | C1: =IFERROR(__xludf.DUMMYFUNCTION("""COMPUTED_VALUE"""),"Nama Lengkap (disertai gelar)") -> Nama Lengkap (disertai gelar) | D1: =IFERROR(__xludf.DUMMYFUNCTION("""COMPUTED_VALUE"""),"PTK ID / SIMPKB ID") -> PTK ID / SIMPKB ID | E1: =IFERROR(__xludf.DUMMYFUNCTION("""COMPUTED_VALUE"""),"Nomor WA") -> Nomor WA | F1: =IFERROR(__xludf.DUMMYFUNCTION("""COMPUTED_VALUE"""),"Tanggal Lahir") -> Tanggal Lahir | G1: =IFERROR(__xludf.DUMMYFUNCTION("""COMPUTED_VALUE"""),"Program Studi S-1/D-IV") -> Program Studi S-1/D-IV | H1: =IFERROR(__xludf.DUMMYFUNCTION("""COMPUTED_VALUE"""),"Asal Universitas S-1/D-IV") -> Asal Universitas S-1/D-IV | I1: =IFERROR(__xludf.DUMMYFUNCTION("""COMPUTED_VALUE"""),"Bidang Studi PPG (sesuai yg tertulis di Serdik)") -> Bidang Studi PPG (sesuai yg tertulis di Serdik) | J1: =IFERROR(__xludf.DUMMYFUNCTION("""COMPUTED_VALUE"""),"Angkatan PPG") -> Angkatan PPG | K1: =IFERROR(__xludf.DUMMYFUNCTION("""COMPUTED_VALUE"""),"Tahun Lulus PPG (sesuai dengan tahun penerbitan Sertifikat Pendidik)") -> Tahun Lulus PPG (sesuai dengan tahun penerbitan Sertifikat Pendidik) | L1: =IFERROR(__xludf.DUMMYFUNCTION("""COMPUTED_VALUE"""),"IPK saat S1") -> IPK saat S1 | M1: =IFERROR(__xludf.DUMMYFUNCTION("""COMPUTED_VALUE"""),"IPK saat PPG") -> IPK saat PPG | N1: =IFERROR(__xludf.DUMMYFUNCTION("""COMPUTED_VALUE"""),"Domisili Anda saat ini? (Contoh : Kota Surakarta, Jawa Tengah)") -> Domisili Anda saat ini? (Contoh : Kota Surakarta, Jawa Tengah) | O1: =IFERROR(__xludf.DUMMYFUNCTION("""COMPUTED_VALUE"""),"Berkedudukan sebagai calon PNS, PNS, PPPK, PPPK Paruh Waktu, prajurit Tentara Nasional Indonesia, atau anggota Kepolisian Negara Republik Indonesia;") -> Berkedudukan sebagai calon PNS, PNS, PPPK, PPPK Paruh Waktu, prajurit Tentara Nasional Indonesia, atau anggota Kepolisian Negara Republik Indonesia; | P1: =IFERROR(__xludf.DUMMYFUNCTION("""COMPUTED_VALUE"""),"Jabatan dan Lokasi TPP yang dilamar") -> Jabatan dan Lokasi TPP yang dilamar | Q1: =IFERROR(__xludf.DUMMYFUNCTION("""COMPUTED_VALUE"""),"Pilihan Lokasi Sekolah Nasional Terintegrasi") -> Pilihan Lokasi Sekolah Nasional Terintegrasi | R1: =IFERROR(__xludf.DUMMYFUNCTION("""COMPUTED_VALUE"""),"Sertifikat Pelatihan Peningkatan Komptenesi (5 tahun terakhir)") -> Sertifikat Pelatihan Peningkatan Komptenesi (5 tahun terakhir) | S1: =IFERROR(__xludf.DUMMYFUNCTION("""COMPUTED_VALUE"""),"Video Microteaching") -> Video Microteaching | T1: =IFERROR(__xludf.DUMMYFUNCTION("""COMPUTED_VALUE"""),"Kategori Pendaftar") -> Kategori Pendaftar | U1: =IFERROR(__xludf.DUMMYFUNCTION("""COMPUTED_VALUE"""),"NIM PPG (dapat dilihat pada web: https://valid.fkip.uns.ac.id)") -> NIM PPG (dapat dilihat pada web: https://valid.fkip.uns.ac.id) | V1: =IFERROR(__xludf.DUMMYFUNCTION("""COMPUTED_VALUE"""),"NIM S1") -> NIM S1 | W1: =IFERROR(__xludf.DUMMYFUNCTION("""COMPUTED_VALUE"""),"Program Studi S1") -> Program Studi S1 | X1: =IFERROR(__xludf.DUMMYFUNCTION("""COMPUTED_VALUE"""),"LPTK PPG") -> LPTK PPG | Y1: =IFERROR(__xludf.DUMMYFUNCTION("""COMPUTED_VALUE"""),"NIM PPG") -> NIM PPG | Z1: =IFERROR(__xludf.DUMMYFUNCTION("""COMPUTED_VALUE"""),"Upload Scan Sertifikat Pendidik (serdik)") -> Upload Scan Sertifikat Pendidik (serdik) | AA1: Hasil Seleksi | AB1: Keterangan
A2: =IFERROR(__xludf.DUMMYFUNCTION("""COMPUTED_VALUE"""),46231.92248826388) -> 46231.922 | B2: =IFERROR(__xludf.DUMMYFUNCTION("""COMPUTED_VALUE"""),"rrizkhyadhi21@gmail.com") -> rrizkhyadhi21@gmail.com | C2: =IFERROR(__xludf.DUMMYFUNCTION("""COMPUTED_VALUE"""),"Rizky Adi Nugroho S.Pd.,Gr.") -> Rizky Adi Nugroho S.Pd.,Gr. | D2: =IFERROR(__xludf.DUMMYFUNCTION("""COMPUTED_VALUE"""),7.000247262E9) -> 7000247262 | E2: =IFERROR(__xludf.DUMMYFUNCTION("""COMPUTED_VALUE"""),"085713086642") -> 085713086642 | F2: =IFERROR(__xludf.DUMMYFUNCTION("""COMPUTED_VALUE"""),36791.0) -> 36791 | G2: =IFERROR(__xludf.DUMMYFUNCTION("""COMPUTED_VALUE"""),"Pendidikan Jasmani") -> Pendidikan Jasmani | H2: =IFERROR(__xludf.DUMMYFUNCTION("""COMPUTED_VALUE"""),"UNIVERSITAS TUNAS PEMBANGUNAN SURAKARTA ") -> UNIVERSITAS TUNAS PEMBANGUNAN SURAKARTA | I2: =IFERROR(__xludf.DUMMYFUNCTION("""COMPUTED_VALUE"""),"Pendidikan Jasmani, Olahraga, dan Kesehatan (PJOK)") -> Pendidikan Jasmani, Olahraga, dan Kesehatan (PJOK) | J2: =IFERROR(__xludf.DUMMYFUNCTION("""COMPUTED_VALUE"""),"PPG Calon Guru Gelombang 2 Tahun 2024") -> PPG Calon Guru Gelombang 2 Tahun 2024 | K2: =IFERROR(__xludf.DUMMYFUNCTION("""COMPUTED_VALUE"""),2025.0) -> 2025 | L2: =IFERROR(__xludf.DUMMYFUNCTION("""COMPUTED_VALUE"""),"3.57") -> 3.57 | M2: =IFERROR(__xludf.DUMMYFUNCTION("""COMPUTED_VALUE"""),"3.88") -> 3.88 | N2: =IFERROR(__xludf.DUMMYFUNCTION("""COMPUTED_VALUE"""),"Sukoharjo, Jawa Tengah") -> Sukoharjo, Jawa Tengah | O2: =IFERROR(__xludf.DUMMYFUNCTION("""COMPUTED_VALUE"""),"Tidak") -> Tidak | P2: =IFERROR(__xludf.DUMMYFUNCTION("""COMPUTED_VALUE"""),"Tenaga pendampingan pembelajaran mata Pelajaran Penjasorkes") -> Tenaga pendampingan pembelajaran mata Pelajaran Penjasorkes | Q2: =IFERROR(__xludf.DUMMYFUNCTION("""COMPUTED_VALUE"""),"Kabupaten Jepara, Jawa Tengah") -> Kabupaten Jepara, Jawa Tengah | R2: =IFERROR(__xludf.DUMMYFUNCTION("""COMPUTED_VALUE"""),"https://drive.google.com/drive/folders/1dsYqEqelctlZxB4Hys2aTvWw_xo7AZBD?usp=drive_link ") -> https://drive.google.com/drive/folders/1dsYqEqelctlZxB4Hys2aTvWw_xo7AZBD?usp=drive_link | S2: =IFERROR(__xludf.DUMMYFUNCTION("""COMPUTED_VALUE"""),"https://drive.google.com/file/d/1iCxSV9hd262CkcTCjL23f6n7t7EoV6ur/view?usp=sharing ") -> https://drive.google.com/file/d/1iCxSV9hd262CkcTCjL23f6n7t7EoV6ur/view?usp=sharing | T2: =IFERROR(__xludf.DUMMYFUNCTION("""COMPUTED_VALUE"""),"Alumni PPG Calon Guru / Prajabatan FKIP UNS") -> Alumni PPG Calon Guru / Prajabatan FKIP UNS | U2: =IFERROR(__xludf.DUMMYFUNCTION("""COMPUTED_VALUE"""),"X942408406") -> X942408406 | V2: =IFERROR(__xludf.DUMMYFUNCTION("""COMPUTED_VALUE"""),"D0418008") -> D0418008 | W2: =IFERROR(__xludf.DUMMYFUNCTION("""COMPUTED_VALUE"""),"PENDIDIKAN JASMANI") -> PENDIDIKAN JASMANI | X2: =IFERROR(__xludf.DUMMYFUNCTION("""COMPUTED_VALUE"""),"UNIVERSITAS SEBELAS MARET SURAKARTA") -> UNIVERSITAS SEBELAS MARET SURAKARTA | Y2: =IFERROR(__xludf.DUMMYFUNCTION("""COMPUTED_VALUE"""),"X942408406") -> X942408406
A3: =IFERROR(__xludf.DUMMYFUNCTION("""COMPUTED_VALUE"""),46229.614621678236) -> 46229.615 | B3: =IFERROR(__xludf.DUMMYFUNCTION("""COMPUTED_VALUE"""),"puspitadianaarumawati@gmail.com") -> puspitadianaarumawati@gmail.com | C3: =IFERROR(__xludf.DUMMYFUNCTION("""COMPUTED_VALUE"""),"Puspita Diana Arumawati, M.Pd., Gr.") -> Puspita Diana Arumawati, M.Pd., Gr. | D3: =IFERROR(__xludf.DUMMYFUNCTION("""COMPUTED_VALUE"""),7.00008667E9) -> 7000086670 | E3: =IFERROR(__xludf.DUMMYFUNCTION("""COMPUTED_VALUE"""),"082313256124") -> 082313256124 | F3: =IFERROR(__xludf.DUMMYFUNCTION("""COMPUTED_VALUE"""),36249.0) -> 36249 | G3: =IFERROR(__xludf.DUMMYFUNCTION("""COMPUTED_VALUE"""),"Pendidikan Biologi") -> Pendidikan Biologi | H3: =IFERROR(__xludf.DUMMYFUNCTION("""COMPUTED_VALUE"""),"Universitas Negeri Semarang") -> Universitas Negeri Semarang | I3: =IFERROR(__xludf.DUMMYFUNCTION("""COMPUTED_VALUE"""),"Biologi") -> Biologi | J3: =IFERROR(__xludf.DUMMYFUNCTION("""COMPUTED_VALUE"""),"PPG Prajabatan Gelombang 2 Tahun 2022") -> PPG Prajabatan Gelombang 2 Tahun 2022 | K3: =IFERROR(__xludf.DUMMYFUNCTION("""COMPUTED_VALUE"""),2023.0) -> 2023 | L3: =IFERROR(__xludf.DUMMYFUNCTION("""COMPUTED_VALUE"""),"3.49") -> 3.49 | M3: =IFERROR(__xludf.DUMMYFUNCTION("""COMPUTED_VALUE"""),"3.94") -> 3.94 | N3: =IFERROR(__xludf.DUMMYFUNCTION("""COMPUTED_VALUE"""),"Kabupaten Boyolali, Jawa Tengah") -> Kabupaten Boyolali, Jawa Tengah | O3: =IFERROR(__xludf.DUMMYFUNCTION("""COMPUTED_VALUE"""),"Tidak") -> Tidak | P3: =IFERROR(__xludf.DUMMYFUNCTION("""COMPUTED_VALUE"""),"Tenaga pendampingan pembelajaran mata Pelajaran Ilmu Pengetahuan Alam (IPA) untuk mengajar mata pelajaran Biologi, Kimia, Fisika") -> Tenaga pendampingan pembelajaran mata Pelajaran Ilmu Pengetahuan Alam (IPA) untuk mengajar mata pelajaran Biologi, Kimia, Fisika | Q3: =IFERROR(__xludf.DUMMYFUNCTION("""COMPUTED_VALUE"""),"Kabupaten Jepara, Jawa Tengah") -> Kabupaten Jepara, Jawa Tengah | R3: =IFERROR(__xludf.DUMMYFUNCTION("""COMPUTED_VALUE"""),"https://drive.google.com/drive/folders/16x0nmGx6I5WGw8jgQGGJwL-c62fCaeiM?usp=drive_link") -> https://drive.google.com/drive/folders/16x0nmGx6I5WGw8jgQGGJwL-c62fCaeiM?usp=drive_link | S3: =IFERROR(__xludf.DUMMYFUNCTION("""COMPUTED_VALUE"""),"https://drive.google.com/drive/folders/1LUwVcKfRJZTw2XbLLprTSDJ04eWDmd0c?usp=sharing") -> https://drive.google.com/drive/folders/1LUwVcKfRJZTw2XbLLprTSDJ04eWDmd0c?usp=sharing | T3: =IFERROR(__xludf.DUMMYFUNCTION("""COMPUTED_VALUE"""),"Alumni PPG Calon Guru / Prajabatan FKIP UNS") -> Alumni PPG Calon Guru / Prajabatan FKIP UNS | U3: =IFERROR(__xludf.DUMMYFUNCTION("""COMPUTED_VALUE"""),"X9022084121") -> X9022084121 | V3: =IFERROR(__xludf.DUMMYFUNCTION("""COMPUTED_VALUE"""),"-") -> - | W3: =IFERROR(__xludf.DUMMYFUNCTION("""COMPUTED_VALUE"""),"-") -> - | X3: =IFERROR(__xludf.DUMMYFUNCTION("""COMPUTED_VALUE"""),"-") -> - | Y3: =IFERROR(__xludf.DUMMYFUNCTION("""COMPUTED_VALUE"""),"-") -> -
A4: =IFERROR(__xludf.DUMMYFUNCTION("""COMPUTED_VALUE"""),46229.615371273154) -> 46229.615 | B4: =IFERROR(__xludf.DUMMYFUNCTION("""COMPUTED_VALUE"""),"hanafifuad33@gmail.com") -> hanafifuad33@gmail.com | C4: =IFERROR(__xludf.DUMMYFUNCTION("""COMPUTED_VALUE"""),"Fuad Hanafi, S.Pd., Gr. ") -> Fuad Hanafi, S.Pd., Gr. | D4: =IFERROR(__xludf.DUMMYFUNCTION("""COMPUTED_VALUE"""),7.000266546E9) -> 7000266546 | E4: =IFERROR(__xludf.DUMMYFUNCTION("""COMPUTED_VALUE"""),"087836197102") -> 087836197102 | F4: =IFERROR(__xludf.DUMMYFUNCTION("""COMPUTED_VALUE"""),37414.0) -> 37414 | G4: =IFERROR(__xludf.DUMMYFUNCTION("""COMPUTED_VALUE"""),"Pendidikan Bahasa dan Sastra Indonesia") -> Pendidikan Bahasa dan Sastra Indonesia | H4: =IFERROR(__xludf.DUMMYFUNCTION("""COMPUTED_VALUE"""),"Universitas Muhammadiyah Surakarta") -> Universitas Muhammadiyah Surakarta | I4: =IFERROR(__xludf.DUMMYFUNCTION("""COMPUTED_VALUE"""),"Bahasa Indonesia") -> Bahasa Indonesia | J4: =IFERROR(__xludf.DUMMYFUNCTION("""COMPUTED_VALUE"""),"PPG Prajabatan Gelombang 1 Tahun 2024") -> PPG Prajabatan Gelombang 1 Tahun 2024 | K4: =IFERROR(__xludf.DUMMYFUNCTION("""COMPUTED_VALUE"""),2025.0) -> 2025 | L4: =IFERROR(__xludf.DUMMYFUNCTION("""COMPUTED_VALUE"""),"3.79") -> 3.79 | M4: =IFERROR(__xludf.DUMMYFUNCTION("""COMPUTED_VALUE"""),"3.86") -> 3.86 | N4: =IFERROR(__xludf.DUMMYFUNCTION("""COMPUTED_VALUE"""),"Sragen, Jawa Tengah") -> Sragen, Jawa Tengah | O4: =IFERROR(__xludf.DUMMYFUNCTION("""COMPUTED_VALUE"""),"Tidak") -> Tidak | P4: =IFERROR(__xludf.DUMMYFUNCTION("""COMPUTED_VALUE"""),"Tenaga pendampingan pembelajaran mata Pelajaran Bahasa Indonesia") -> Tenaga pendampingan pembelajaran mata Pelajaran Bahasa Indonesia | Q4: =IFERROR(__xludf.DUMMYFUNCTION("""COMPUTED_VALUE"""),"Kabupaten Jepara, Jawa Tengah") -> Kabupaten Jepara, Jawa Tengah | R4: =IFERROR(__xludf.DUMMYFUNCTION("""COMPUTED_VALUE"""),"https://drive.google.com/drive/folders/1sbX_gWwophHrTMrZOyC0f5Nbdw36cMSx") -> https://drive.google.com/drive/folders/1sbX_gWwophHrTMrZOyC0f5Nbdw36cMSx | S4: =IFERROR(__xludf.DUMMYFUNCTION("""COMPUTED_VALUE"""),"https://drive.google.com/drive/folders/1nSG76BaQdtMG-CDvZEJRGPQJe22CUPnC") -> https://drive.google.com/drive/folders/1nSG76BaQdtMG-CDvZEJRGPQJe22CUPnC | T4: =IFERROR(__xludf.DUMMYFUNCTION("""COMPUTED_VALUE"""),"Alumni PPG Calon Guru / Prajabatan FKIP UNS") -> Alumni PPG Calon Guru / Prajabatan FKIP UNS | U4: =IFERROR(__xludf.DUMMYFUNCTION("""COMPUTED_VALUE"""),"X942408195") -> X942408195 | V4: =IFERROR(__xludf.DUMMYFUNCTION("""COMPUTED_VALUE"""),"-") -> - | W4: =IFERROR(__xludf.DUMMYFUNCTION("""COMPUTED_VALUE"""),"-") -> - | X4: =IFERROR(__xludf.DUMMYFUNCTION("""COMPUTED_VALUE"""),"Universitas Sebelas Maret") -> Universitas Sebelas Maret | Y4: =IFERROR(__xludf.DUMMYFUNCTION("""COMPUTED_VALUE"""),"-") -> -
A5: =IFERROR(__xludf.DUMMYFUNCTION("""COMPUTED_VALUE"""),46230.94699185185) -> 46230.947 | B5: =IFERROR(__xludf.DUMMYFUNCTION("""COMPUTED_VALUE"""),"nalapawitri81@gmail.com") -> nalapawitri81@gmail.com | C5: =IFERROR(__xludf.DUMMYFUNCTION("""COMPUTED_VALUE"""),"Nala Pawitri Andanawarih, S.Pd.,Gr") -> Nala Pawitri Andanawarih, S.Pd.,Gr | D5: =IFERROR(__xludf.DUMMYFUNCTION("""COMPUTED_VALUE"""),7.000088952E9) -> 7000088952 | E5: =IFERROR(__xludf.DUMMYFUNCTION("""COMPUTED_VALUE"""),"089515819690") -> 089515819690 | F5: =IFERROR(__xludf.DUMMYFUNCTION("""COMPUTED_VALUE"""),36154.0) -> 36154 | G5: =IFERROR(__xludf.DUMMYFUNCTION("""COMPUTED_VALUE"""),"Pendidikan Seni Tari") -> Pendidikan Seni Tari | H5: =IFERROR(__xludf.DUMMYFUNCTION("""COMPUTED_VALUE"""),"Universitas Negeri Semarang") -> Universitas Negeri Semarang | I5: =IFERROR(__xludf.DUMMYFUNCTION("""COMPUTED_VALUE"""),"Seni Budaya") -> Seni Budaya | J5: =IFERROR(__xludf.DUMMYFUNCTION("""COMPUTED_VALUE"""),"PPG Prajabatan Gelombang 1 Tahun 2023") -> PPG Prajabatan Gelombang 1 Tahun 2023 | K5: =IFERROR(__xludf.DUMMYFUNCTION("""COMPUTED_VALUE"""),2024.0) -> 2024 | L5: =IFERROR(__xludf.DUMMYFUNCTION("""COMPUTED_VALUE"""),"3.28") -> 3.28 | M5: =IFERROR(__xludf.DUMMYFUNCTION("""COMPUTED_VALUE"""),"3.86") -> 3.86 | N5: =IFERROR(__xludf.DUMMYFUNCTION("""COMPUTED_VALUE"""),"Banyumas, Jawa Tengah") -> Banyumas, Jawa Tengah | O5: =IFERROR(__xludf.DUMMYFUNCTION("""COMPUTED_VALUE"""),"Tidak") -> Tidak | P5: =IFERROR(__xludf.DUMMYFUNCTION("""COMPUTED_VALUE"""),"Tenaga pendampingan pembelajaran mata Pelajaran Seni, Budaya, dan Prakarya") -> Tenaga pendampingan pembelajaran mata Pelajaran Seni, Budaya, dan Prakarya | Q5: =IFERROR(__xludf.DUMMYFUNCTION("""COMPUTED_VALUE"""),"Kabupaten Jepara, Jawa Tengah") -> Kabupaten Jepara, Jawa Tengah | R5: =IFERROR(__xludf.DUMMYFUNCTION("""COMPUTED_VALUE"""),"-") -> - | S5: =IFERROR(__xludf.DUMMYFUNCTION("""COMPUTED_VALUE"""),"https://drive.google.com/drive/folders/1yCvx2arxXyITby30A4zMMaHb1zIP3NMt?hl=ID ") -> https://drive.google.com/drive/folders/1yCvx2arxXyITby30A4zMMaHb1zIP3NMt?hl=ID | T5: =IFERROR(__xludf.DUMMYFUNCTION("""COMPUTED_VALUE"""),"Alumni PPG Calon Guru / Prajabatan FKIP UNS") -> Alumni PPG Calon Guru / Prajabatan FKIP UNS | U5: =IFERROR(__xludf.DUMMYFUNCTION("""COMPUTED_VALUE"""),"X902308613") -> X902308613 | V5: =IFERROR(__xludf.DUMMYFUNCTION("""COMPUTED_VALUE"""),"2501417040") -> 2501417040 | W5: =IFERROR(__xludf.DUMMYFUNCTION("""COMPUTED_VALUE"""),"Pendidikan Seni Tari ") -> Pendidikan Seni Tari | X5: =IFERROR(__xludf.DUMMYFUNCTION("""COMPUTED_VALUE"""),"Universitas Sebelas Maret (UNS)") -> Universitas Sebelas Maret (UNS) | Y5: =IFERROR(__xludf.DUMMYFUNCTION("""COMPUTED_VALUE"""),"X902308613") -> X902308613
A6: =IFERROR(__xludf.DUMMYFUNCTION("""COMPUTED_VALUE"""),46229.62515537037) -> 46229.625 | B6: =IFERROR(__xludf.DUMMYFUNCTION("""COMPUTED_VALUE"""),"zahraarqam@gmail.com") -> zahraarqam@gmail.com | C6: =IFERROR(__xludf.DUMMYFUNCTION("""COMPUTED_VALUE"""),"Sitti Zahra Riarana Arqam, S.Pd.Gr") -> Sitti Zahra Riarana Arqam, S.Pd.Gr | D6: =IFERROR(__xludf.DUMMYFUNCTION("""COMPUTED_VALUE"""),7.00216115E8) -> 700216115 | E6: =IFERROR(__xludf.DUMMYFUNCTION("""COMPUTED_VALUE"""),"085399527002") -> 085399527002 | F6: =IFERROR(__xludf.DUMMYFUNCTION("""COMPUTED_VALUE"""),34744.0) -> 34744 | G6: =IFERROR(__xludf.DUMMYFUNCTION("""COMPUTED_VALUE"""),"Pendidikan Jasmani, Kesehatan dan Rekreasi") -> Pendidikan Jasmani, Kesehatan dan Rekreasi | H6: =IFERROR(__xludf.DUMMYFUNCTION("""COMPUTED_VALUE"""),"Universitas Halu Oleo") -> Universitas Halu Oleo | I6: =IFERROR(__xludf.DUMMYFUNCTION("""COMPUTED_VALUE"""),"Pendidikan Jasmani, Olahraga, dan Kesehatan (PJOK)") -> Pendidikan Jasmani, Olahraga, dan Kesehatan (PJOK) | J6: =IFERROR(__xludf.DUMMYFUNCTION("""COMPUTED_VALUE"""),"PPG Calon Guru Gelombang 2 Tahun 2024") -> PPG Calon Guru Gelombang 2 Tahun 2024 | K6: =IFERROR(__xludf.DUMMYFUNCTION("""COMPUTED_VALUE"""),2025.0) -> 2025 | L6: =IFERROR(__xludf.DUMMYFUNCTION("""COMPUTED_VALUE"""),"3.35") -> 3.35 | M6: =IFERROR(__xludf.DUMMYFUNCTION("""COMPUTED_VALUE"""),"4.00") -> 4.00 | N6: =IFERROR(__xludf.DUMMYFUNCTION("""COMPUTED_VALUE"""),"Kota kendari, Sulawesi Tenggara") -> Kota kendari, Sulawesi Tenggara | O6: =IFERROR(__xludf.DUMMYFUNCTION("""COMPUTED_VALUE"""),"Tidak") -> Tidak | P6: =IFERROR(__xludf.DUMMYFUNCTION("""COMPUTED_VALUE"""),"Tenaga pendampingan pembelajaran mata Pelajaran Penjasorkes") -> Tenaga pendampingan pembelajaran mata Pelajaran Penjasorkes | Q6: =IFERROR(__xludf.DUMMYFUNCTION("""COMPUTED_VALUE"""),"Kabupaten Buton Tengah, Sulawesi Tenggara") -> Kabupaten Buton Tengah, Sulawesi Tenggara | R6: =IFERROR(__xludf.DUMMYFUNCTION("""COMPUTED_VALUE"""),"https://drive.google.com/file/d/1RTVKYZC70VNFZ0Li44B1okppAyidoSP2/view?usp=sharing") -> https://drive.google.com/file/d/1RTVKYZC70VNFZ0Li44B1okppAyidoSP2/view?usp=sharing | S6: =IFERROR(__xludf.DUMMYFUNCTION("""COMPUTED_VALUE"""),"https://drive.google.com/drive/folders/1v7ET-0MLyK3nfkDv6QSCOQu7jdaH58zl") -> https://drive.google.com/drive/folders/1v7ET-0MLyK3nfkDv6QSCOQu7jdaH58zl | T6: =IFERROR(__xludf.DUMMYFUNCTION("""COMPUTED_VALUE"""),"Alumni PPG Calon Guru / Prajabatan FKIP UHO") -> Alumni PPG Calon Guru / Prajabatan FKIP UHO | Y6: =IFERROR(__xludf.DUMMYFUNCTION("""COMPUTED_VALUE"""),"A3S224349") -> A3S224349
A7: =IFERROR(__xludf.DUMMYFUNCTION("""COMPUTED_VALUE"""),46229.727876377314) -> 46229.728 | B7: =IFERROR(__xludf.DUMMYFUNCTION("""COMPUTED_VALUE"""),"ppg.syahnadinnuridha91@program.belajar.id") -> ppg.syahnadinnuridha91@program.belajar.id | C7: =IFERROR(__xludf.DUMMYFUNCTION("""COMPUTED_VALUE"""),"SYAHNADIN NURIDHA, S. Pd., Gr") -> SYAHNADIN NURIDHA, S. Pd., Gr | D7: =IFERROR(__xludf.DUMMYFUNCTION("""COMPUTED_VALUE"""),7.000141094E9) -> 7000141094 | E7: =IFERROR(__xludf.DUMMYFUNCTION("""COMPUTED_VALUE"""),"082322016171") -> 082322016171 | F7: =IFERROR(__xludf.DUMMYFUNCTION("""COMPUTED_VALUE"""),36178.0) -> 36178 | G7: =IFERROR(__xludf.DUMMYFUNCTION("""COMPUTED_VALUE"""),"S1 PENDIDIKAN IPA") -> S1 PENDIDIKAN IPA | H7: =IFERROR(__xludf.DUMMYFUNCTION("""COMPUTED_VALUE"""),"UNIVERSITAS NEGERI SEMARANG") -> UNIVERSITAS NEGERI SEMARANG | I7: =IFERROR(__xludf.DUMMYFUNCTION("""COMPUTED_VALUE"""),"Ilmu Pengetahuan Alam (IPA)") -> Ilmu Pengetahuan Alam (IPA) | J7: =IFERROR(__xludf.DUMMYFUNCTION("""COMPUTED_VALUE"""),"PPG Prajabatan Gelombang 1 Tahun 2023") -> PPG Prajabatan Gelombang 1 Tahun 2023 | K7: =IFERROR(__xludf.DUMMYFUNCTION("""COMPUTED_VALUE"""),2024.0) -> 2024 | L7: =IFERROR(__xludf.DUMMYFUNCTION("""COMPUTED_VALUE"""),"3.45") -> 3.45 | M7: =IFERROR(__xludf.DUMMYFUNCTION("""COMPUTED_VALUE"""),"3.94") -> 3.94 | N7: =IFERROR(__xludf.DUMMYFUNCTION("""COMPUTED_VALUE"""),"SURAKARTA") -> SURAKARTA | O7: =IFERROR(__xludf.DUMMYFUNCTION("""COMPUTED_VALUE"""),"Tidak") -> Tidak | P7: =IFERROR(__xludf.DUMMYFUNCTION("""COMPUTED_VALUE"""),"Tenaga pendampingan pembelajaran mata Pelajaran Ilmu Pengetahuan Alam (IPA) untuk mengajar mata pelajaran Biologi, Kimia, Fisika") -> Tenaga pendampingan pembelajaran mata Pelajaran Ilmu Pengetahuan Alam (IPA) untuk mengajar mata pelajaran Biologi, Kimia, Fisika | Q7: =IFERROR(__xludf.DUMMYFUNCTION("""COMPUTED_VALUE"""),"Kabupaten Jepara, Jawa Tengah") -> Kabupaten Jepara, Jawa Tengah | R7: =IFERROR(__xludf.DUMMYFUNCTION("""COMPUTED_VALUE"""),"https://drive.google.com/drive/folders/1zI1VsvS3r7N2xgGHzHSOeXsPBlYpL9ku?usp=sharing") -> https://drive.google.com/drive/folders/1zI1VsvS3r7N2xgGHzHSOeXsPBlYpL9ku?usp=sharing | S7: =IFERROR(__xludf.DUMMYFUNCTION("""COMPUTED_VALUE"""),"https://drive.google.com/drive/folders/1zI1VsvS3r7N2xgGHzHSOeXsPBlYpL9ku?usp=sharing") -> https://drive.google.com/drive/folders/1zI1VsvS3r7N2xgGHzHSOeXsPBlYpL9ku?usp=sharing | T7: =IFERROR(__xludf.DUMMYFUNCTION("""COMPUTED_VALUE"""),"Alumni PPG Calon Guru / Prajabatan FKIP UNS") -> Alumni PPG Calon Guru / Prajabatan FKIP UNS | U7: =IFERROR(__xludf.DUMMYFUNCTION("""COMPUTED_VALUE"""),"X902308868") -> X902308868 | V7: =IFERROR(__xludf.DUMMYFUNCTION("""COMPUTED_VALUE"""),"4001417039") -> 4001417039 | W7: =IFERROR(__xludf.DUMMYFUNCTION("""COMPUTED_VALUE"""),"PENDIDIKAN IPA") -> PENDIDIKAN IPA | X7: =IFERROR(__xludf.DUMMYFUNCTION("""COMPUTED_VALUE"""),"UNIVERSITAS SEBELAS MARET") -> UNIVERSITAS SEBELAS MARET | Y7: =IFERROR(__xludf.DUMMYFUNCTION("""COMPUTED_VALUE"""),"X902308868") -> X902308868
A8: =IFERROR(__xludf.DUMMYFUNCTION("""COMPUTED_VALUE"""),46231.35516229167) -> 46231.355 | B8: =IFERROR(__xludf.DUMMYFUNCTION("""COMPUTED_VALUE"""),"syiadwi13@gmail.com") -> syiadwi13@gmail.com | C8: =IFERROR(__xludf.DUMMYFUNCTION("""COMPUTED_VALUE"""),"Syifa Dwi Novita, S.Pd., Gr.") -> Syifa Dwi Novita, S.Pd., Gr. | D8: =IFERROR(__xludf.DUMMYFUNCTION("""COMPUTED_VALUE"""),7.000012366E9) -> 7000012366 | E8: =IFERROR(__xludf.DUMMYFUNCTION("""COMPUTED_VALUE"""),"089608882627") -> 089608882627 | F8: =IFERROR(__xludf.DUMMYFUNCTION("""COMPUTED_VALUE"""),35747.0) -> 35747 | G8: =IFERROR(__xludf.DUMMYFUNCTION("""COMPUTED_VALUE"""),"S1 Pendidikan Biologi") -> S1 Pendidikan Biologi | H8: =IFERROR(__xludf.DUMMYFUNCTION("""COMPUTED_VALUE"""),"Universitas Muhammadiyah Purwokerto") -> Universitas Muhammadiyah Purwokerto | I8: =IFERROR(__xludf.DUMMYFUNCTION("""COMPUTED_VALUE"""),"Ilmu Pengetahuan Alam (IPA)") -> Ilmu Pengetahuan Alam (IPA) | J8: =IFERROR(__xludf.DUMMYFUNCTION("""COMPUTED_VALUE"""),"PPG Prajabatan Gelombang 1 Tahun 2023") -> PPG Prajabatan Gelombang 1 Tahun 2023 | K8: =IFERROR(__xludf.DUMMYFUNCTION("""COMPUTED_VALUE"""),2024.0) -> 2024 | L8: =IFERROR(__xludf.DUMMYFUNCTION("""COMPUTED_VALUE"""),"3.36") -> 3.36 | M8: =IFERROR(__xludf.DUMMYFUNCTION("""COMPUTED_VALUE"""),"3.98") -> 3.98 | N8: =IFERROR(__xludf.DUMMYFUNCTION("""COMPUTED_VALUE"""),"Kedungrandu RT 1 RW 3, Kecamatan Patikraja, Kabupaten Banyumas") -> Kedungrandu RT 1 RW 3, Kecamatan Patikraja, Kabupaten Banyumas | O8: =IFERROR(__xludf.DUMMYFUNCTION("""COMPUTED_VALUE"""),"Tidak") -> Tidak | P8: =IFERROR(__xludf.DUMMYFUNCTION("""COMPUTED_VALUE"""),"Tenaga pendampingan pembelajaran mata Pelajaran Ilmu Pengetahuan Alam (IPA) untuk mengajar mata pelajaran Biologi, Kimia, Fisika") -> Tenaga pendampingan pembelajaran mata Pelajaran Ilmu Pengetahuan Alam (IPA) untuk mengajar mata pelajaran Biologi, Kimia, Fisika | Q8: =IFERROR(__xludf.DUMMYFUNCTION("""COMPUTED_VALUE"""),"Kabupaten Jepara, Jawa Tengah") -> Kabupaten Jepara, Jawa Tengah | R8: =IFERROR(__xludf.DUMMYFUNCTION("""COMPUTED_VALUE"""),"https://drive.google.com/file/d/1X90srqhGWSBgzBIWf55Q0lMEEvUwXmVt/view?usp=sharing") -> https://drive.google.com/file/d/1X90srqhGWSBgzBIWf55Q0lMEEvUwXmVt/view?usp=sharing | S8: =IFERROR(__xludf.DUMMYFUNCTION("""COMPUTED_VALUE"""),"https://drive.google.com/drive/folders/1sDPOjTor3XOExzch1Qzi6KmtuS5XvMav?usp=drive_link") -> https://drive.google.com/drive/folders/1sDPOjTor3XOExzch1Qzi6KmtuS5XvMav?usp=drive_link | T8: =IFERROR(__xludf.DUMMYFUNCTION("""COMPUTED_VALUE"""),"Alumni PPG Calon Guru / Prajabatan FKIP UNS") -> Alumni PPG Calon Guru / Prajabatan FKIP UNS | U8: =IFERROR(__xludf.DUMMYFUNCTION("""COMPUTED_VALUE"""),"X902308871") -> X902308871 | V8: =IFERROR(__xludf.DUMMYFUNCTION("""COMPUTED_VALUE"""),"1501070008") -> 1501070008 | W8: =IFERROR(__xludf.DUMMYFUNCTION("""COMPUTED_VALUE"""),"S1 Pendidikan Biologi") -> S1 Pendidikan Biologi | X8: =IFERROR(__xludf.DUMMYFUNCTION("""COMPUTED_VALUE"""),"Universitas Sebelas Maret") -> Universitas Sebelas Maret | Y8: =IFERROR(__xludf.DUMMYFUNCTION("""COMPUTED_VALUE"""),"-") -> -
